<robot name="dyros_jet_robot">
  <link name="world"/>
  <joint name = "virtual" type="floating">
    <origin xyz="0 0 0" rpy="0 0 0" />
    <parent link ="world"/>
    <child link="waistpitch_link"/>
    <limit effort="30" velocity="1.0" lower="-3.14" upper="3.14"/>
  </joint>

  <link name="base_link">
    <inertial>
      <origin xyz="0 0 0.08027" rpy="0 0 0" />
      <mass 
	value="3.90994" />
      <inertia
        ixx="0.02724195938"
        ixy="0"
        ixz="0"
        iyy="0.00634115870"
        iyz="0"
        izz="0.02399190431" />
    </inertial>
    <visual>
      <origin
        xyz="0 0 0"
        rpy="0 0 0" />
      <geometry>
        <mesh filename="package://dyros_jet_description/meshes/base_link.stl" />
      </geometry>
      <material
        name="">
        <color rgba="0.59216 0.61961 0.65098 1" />
      </material>
    </visual>
    <collision>
      <origin
        xyz="0 0 0"
        rpy="0 0 0" />
      <geometry>
        <mesh
          filename="package://dyros_jet_description/meshes/base_link.stl" />
      </geometry> 
    </collision>
  </link>
  <link name="L_HipYaw_Link">
    <inertial>
      <origin
        xyz="-0.02955 0 0.06943"
        rpy="0 0 0" />
      <mass 
	value="1.54216" />
      <inertia
        ixx="0.00412070145"
        ixy="0"
        ixz="0.00089593414"
        iyy="0.00664372362"
        iyz="-0.0000003791"
        izz="0.00338413515" />
    </inertial>
    <visual>
      <origin
        xyz="0 0 0"
        rpy="0 0 0" />
      <geometry>
        <mesh
          filename="package://dyros_jet_description/meshes/hip_yaw.stl" />
      </geometry>
      <material
        name="">
        <color
          rgba="0.59216 0.61961 0.65098 1" />
      </material>
    </visual>
    <collision>
      <origin
        xyz="0 0 0"
        rpy="0 0 0" />
      <geometry>
        <mesh
          filename="package://dyros_jet_description/meshes/hip_yaw.stl" />
      </geometry>
    </collision>
  </link>
  <joint
    name="L_HipYaw"
    type="revolute">
    <origin
      xyz="0 0.105 -0.11190"
      rpy="0 0 0" />
    <parent
      link="base_link" />
    <child
      link="L_HipYaw_Link" />
    <axis
      xyz="0 0 -1" />
    <limit
      effort="30"
      velocity="1" lower="-3.14" upper="3.14" />
  </joint>
  <link
    name="L_HipRoll_Link">
    <inertial>
      <origin
        xyz="0.00513 -0.00119 0"
        rpy="0 0 0" />
      <mass
        value="1.16907" />
      <inertia
        ixx="0.00180677428"
        ixy="0.00000973989"
        ixz="0.00000040230"
        iyy="0.00087972680"
        iyz="-0.000033160"
        izz="0.00199196267" />
    </inertial>
    <visual>
      <origin
        xyz="0 0 0"
        rpy="0 0 0" />
      <geometry>
        <mesh
          filename="package://dyros_jet_description/meshes/hip_roll.stl" />
      </geometry>
      <material
        name="">
        <color
          rgba="0.59216 0.61961 0.65098 1" />
      </material>
    </visual>
    <collision>
      <origin
        xyz="0 0 0"
        rpy="0 0 0" />
      <geometry>
        <mesh
          filename="package://dyros_jet_description/meshes/hip_roll.stl" />
      </geometry>
    </collision>
  </link>
  <joint
    name="L_HipRoll"
    type="revolute">
    <origin
      xyz="0 0 0"
      rpy="0 0 0" />
    <parent
      link="L_HipYaw_Link" />
    <child
      link="L_HipRoll_Link" />
    <axis
      xyz="1 0 0" />
    <limit
      effort="30"
      velocity="1" lower="-3.14" upper="3.14" />
  </joint>
  <link
    name="L_HipPitch_Link">
    <inertial>
      <origin
        xyz="0.12203 0.00306 -0.23316"
        rpy="0 0 0" />
      <mass
        value="3.28269" />
      <inertia
        ixx="0.04026422334"
        ixy="-0.00122469549"
        ixz="-0.01390323874"
        iyy="0.04329246922"
        iyz="0.00234011199"
        izz="0.01768138410" />
    </inertial>
    <visual>
      <origin
        xyz="0 0 0"
        rpy="0 0 0" />
      <geometry>
        <mesh
          filename="package://dyros_jet_description/meshes/hip_pitch.stl" />
      </geometry>
      <material
        name="">
        <color
          rgba="0.59216 0.61961 0.65098 1" />
      </material>
    </visual>
    <collision>
      <origin
        xyz="0 0 0"
        rpy="0 0 0" />
      <geometry>
        <mesh
          filename="package://dyros_jet_description/meshes/hip_pitch.stl" />
      </geometry>
    </collision>
  </link>
  <joint
    name="L_HipPitch"
    type="revolute">
    <origin
      xyz="0 0 0"
      rpy="0 0 0" />
    <parent
      link="L_HipRoll_Link" />
    <child
      link="L_HipPitch_Link" />
    <axis
      xyz="0 1 0" />
    <limit
      effort="30"
      velocity="1" lower="-3.14" upper="3.14" />
  </joint>
  <link
    name="L_KneePitch_Link">
    <inertial>
      <origin
        xyz="0.05276 -0.01856 -0.22635"
        rpy="0 0 0" />
      <mass
        value="2.04524" />
      <inertia
        ixx="0.03535528788"
        ixy="0.00087858758"
        ixz="-0.00310465960"
        iyy="0.03128221988"
        iyz="0.00677319603"
        izz="0.00677705818" />
    </inertial>
    <visual>
      <origin
        xyz="0 0 0"
        rpy="0 0 0" />
      <geometry>
        <mesh
          filename="package://dyros_jet_description/meshes/left_shin.stl" />
      </geometry>
      <material
        name="">
        <color
          rgba="0.59216 0.61961 0.65098 1" />
      </material>
    </visual>
    <collision>
      <origin
        xyz="0 0 0"
        rpy="0 0 0" />
      <geometry>
        <mesh
          filename="package://dyros_jet_description/meshes/left_shin.stl" />
      </geometry>
    </collision>
  </link>
  <joint
    name="L_KneePitch"
    type="revolute">
    <origin
      xyz="0.1515 0 -0.339"
      rpy="0 0 0" />
    <parent
      link="L_HipPitch_Link" />
    <child
      link="L_KneePitch_Link" />
    <axis
      xyz="0 1 0" />
    <limit
      effort="30"
      velocity="1" lower="-3.14" upper="3.14" />
  </joint>
  <link
    name="L_AnklePitch_Link">
    <inertial>
      <origin
        xyz="-0.01035 0.00568 0"
        rpy="0 0 0" />
      <mass
        value="1.18450" />
      <inertia
        ixx="0.00091081511"
        ixy="0.00006964019"
        ixz="0.000002848"
        iyy="0.00185149782"
        iyz="-0.0000062320"
        izz="0.00206162879" />
    </inertial>
    <visual>
      <origin
        xyz="0 0 0"
        rpy="0 0 0" />
      <geometry>
        <mesh
          filename="package://dyros_jet_description/meshes/left_ankle_pitch.stl" />
      </geometry>
      <material
        name="">
        <color
          rgba="0.59216 0.61961 0.65098 1" />
      </material>
    </visual>
    <collision>
      <origin
        xyz="0 0 0"
        rpy="0 0 0" />
      <geometry>
        <mesh
          filename="package://dyros_jet_description/meshes/left_ankle_pitch.stl" />
      </geometry>
    </collision>
  </link>
  <joint
    name="L_AnklePitch"
    type="revolute">
    <origin
      xyz="0.06 0 -0.368"
      rpy="0 0 0" />
    <parent
      link="L_KneePitch_Link" />
    <child
      link="L_AnklePitch_Link" />
    <axis
      xyz="0 1 0" />
    <limit
      effort="30"
      velocity="1" lower="-3.14" upper="3.14" />
  </joint>
  <link
    name="L_AnkleRoll_Link">
    <inertial>
      <origin
        xyz="-0.00989 0 0.07224"
        rpy="0 0 0" />
      <mass
        value="1.42541" />
      <inertia
        ixx="0.00349247764"
        ixy="-0.0000003495"
        ixz="-0.00086859128"
        iyy="0.00816767704"
        iyz="-0.0000001029"
        izz="0.00895530984" />
    </inertial>
    <visual>
      <origin
        xyz="0 0 0"
        rpy="0 0 0" />
      <geometry>
        <mesh
          filename="package://dyros_jet_description/meshes/ankle_roll.stl" />
      </geometry>
      <material
        name="">
        <color
          rgba="0.59216 0.61961 0.65098 1" />
      </material>
    </visual>
    <collision>
      <origin
        xyz="0 0 0"
        rpy="0 0 0" />
      <geometry>
        <mesh
          filename="package://dyros_jet_description/meshes/ankle_roll.stl" />
      </geometry>
    </collision>
  </link>
  <joint
    name="L_AnkleRoll"
    type="revolute">
    <origin
      xyz="0 0 0"
      rpy="0 0 0" />
    <parent
      link="L_AnklePitch_Link" />
    <child
      link="L_AnkleRoll_Link" />
    <axis
      xyz="1 0 0" />
    <limit
      effort="30"
      velocity="1" lower="-3.14" upper="3.14" />
  </joint>
  <link
    name="R_HipYaw_Link">
    <inertial>
      <origin
        xyz="-0.02955 0 0.06943"
        rpy="0 0 0" />
      <mass
        value="1.54216" />
      <inertia
        ixx="0.00412070145"
        ixy="0.0000009012"
        ixz="0.00089593414"
        iyy="0.00664372362"
        iyz="-0.0000003794"
        izz="0.00338413515" />
    </inertial>
    <visual>
      <origin
        xyz="0 0 0"
        rpy="0 0 0" />
      <geometry>
        <mesh
          filename="package://dyros_jet_description/meshes/hip_yaw.stl" />
      </geometry>
      <material
        name="">
        <color
          rgba="0.59216 0.61961 0.65098 1" />
      </material>
    </visual>
    <collision>
      <origin
        xyz="0 0 0"
        rpy="0 0 0" />
      <geometry>
        <mesh
          filename="package://dyros_jet_description/meshes/hip_yaw.stl" />
      </geometry>
    </collision>
  </link>
  <joint
    name="R_HipYaw"
    type="revolute">
    <origin
      xyz="0 -0.105 -0.11190"
      rpy="0 0 0" />
    <parent
      link="base_link" />
    <child
      link="R_HipYaw_Link" />
    <axis
      xyz="0 0 -1" />
    <limit
      effort="30"
      velocity="1" lower="-3.14" upper="3.14" />
  </joint>
  <link
    name="R_HipRoll_Link">
    <inertial>
      <origin
        xyz="0.00513 0.00119 0"
        rpy="0 0 0" />
      <mass
        value="1.16907" />
      <inertia
        ixx="0.00180677428"
        ixy="-0.00000973989"
        ixz="0.0000004386"
        iyy="0.00087972680"
        iyz="0.00003322"
        izz="0.00199196267" />
    </inertial>
    <visual>
      <origin
        xyz="0 0 0"
        rpy="0 0 0" />
      <geometry>
        <mesh
          filename="package://dyros_jet_description/meshes/hip_roll.stl" />
      </geometry>
      <material
        name="">
        <color
          rgba="0.59216 0.61961 0.65098 1" />
      </material>
    </visual>
    <collision>
      <origin
        xyz="0 0 0"
        rpy="0 0 0" />
      <geometry>
        <mesh
          filename="package://dyros_jet_description/meshes/hip_roll.stl" />
      </geometry>
    </collision>
  </link>
  <joint
    name="R_HipRoll"
    type="revolute">
    <origin
      xyz="0 0 0"
      rpy="0 0 0" />
    <parent
      link="R_HipYaw_Link" />
    <child
      link="R_HipRoll_Link" />
    <axis
      xyz="1 0 0" />
    <limit
      effort="30"
      velocity="1" lower="-3.14" upper="3.14" />
  </joint>
  <link
    name="R_HipPitch_Link">
    <inertial>
      <origin
        xyz="0.11203 -0.00306 -0.23316"
        rpy="0 0 0" />
      <mass
        value="3.28269" />
      <inertia
        ixx="0.04026423334"
        ixy="0.00122469549"
        ixz="-0.01390323874"
        iyy="0.04329246922"
        iyz="-0.00233982906"
        izz="0.01768138410" />
    </inertial>
    <visual>
      <origin
        xyz="0 0 0"
        rpy="0 0 0" />
      <geometry>
        <mesh
          filename="package://dyros_jet_description/meshes/hip_pitch.stl" />
      </geometry>
      <material
        name="">
        <color
          rgba="0.59216 0.61961 0.65098 1" />
      </material>
    </visual>
    <collision>
      <origin
        xyz="0 0 0"
        rpy="0 0 0" />
      <geometry>
        <mesh
          filename="package://dyros_jet_description/meshes/hip_pitch.stl" />
      </geometry>
    </collision>
  </link>
  <joint
    name="R_HipPitch"
    type="revolute">
    <origin
      xyz="0 0 0"
      rpy="0 0 0" />
    <parent
      link="R_HipRoll_Link" />
    <child
      link="R_HipPitch_Link" />
    <axis
      xyz="0 -1 0" />
    <limit
      effort="30"
      velocity="1" lower="-3.14" upper="3.14" />
  </joint>
  <link
    name="R_KneePitch_Link">
    <inertial>
      <origin
        xyz="0.05276 0.01856 -0.22635"
        rpy="0 0 0" />
      <mass
        value="2.04524" />
      <inertia
        ixx="0.03537964069"
        ixy="-0.002045"
        ixz="-0.007079"
        iyy="0.03129299830"
        iyz="-0.002961"
        izz="0.00679475749" />
    </inertial>
    <visual>
      <origin
        xyz="0 0 0"
        rpy="0 0 0" />
      <geometry>
        <mesh
          filename="package://dyros_jet_description/meshes/right_shin.stl" />
      </geometry>
      <material
        name="">
        <color
          rgba="0.59216 0.61961 0.65098 1" />
      </material>
    </visual>
    <collision>
      <origin
        xyz="0 0 0"
        rpy="0 0 0" />
      <geometry>
        <mesh
          filename="package://dyros_jet_description/meshes/right_shin.stl" />
      </geometry>
    </collision>
  </link>
  <joint
    name="R_KneePitch"
    type="revolute">
    <origin
      xyz="0.1515 0 -0.339"
      rpy="0 0 0" />
    <parent
      link="R_HipPitch_Link" />
    <child
      link="R_KneePitch_Link" />
    <axis
      xyz="0 -1 0" />
    <limit
      effort="30"
      velocity="1" lower="-3.14" upper="3.14" />
  </joint>
  <link
    name="R_AnklePitch_Link">
    <inertial>
      <origin
        xyz="-0.01035 0.00568 0"
        rpy="0 0 0" />
      <mass
        value="1.18450" />
      <inertia
        ixx="0.00091077271"
        ixy="-0.00006959439"
        ixz="0.000002857"
        iyy="0.00185147541"
        iyz="0.000006241"
        izz="0.00206164878" />
    </inertial>
    <visual>
      <origin
        xyz="0 0 0"
        rpy="0 0 0" />
      <geometry>
        <mesh
          filename="package://dyros_jet_description/meshes/right_ankle_pitch.stl" />
      </geometry>
      <material
        name="">
        <color
          rgba="0.59216 0.61961 0.65098 1" />
      </material>
    </visual>
    <collision>
      <origin
        xyz="0 0 0"
        rpy="0 0 0" />
      <geometry>
        <mesh
          filename="package://dyros_jet_description/meshes/right_ankle_pitch.stl" />
      </geometry>
    </collision>
  </link>
  <joint
    name="R_AnklePitch"
    type="revolute">
    <origin
      xyz="0.06 0 -0.368"
      rpy="0 0 0" />
    <parent
      link="R_KneePitch_Link" />
    <child
      link="R_AnklePitch_Link" />
    <axis
      xyz="0 -1 0" />
    <limit
      effort="30"
      velocity="1" lower="-3.14" upper="3.14" />
  </joint>
  <link
    name="R_AnkleRoll_Link">
    <inertial>
      <origin
        xyz="-0.00989 0 0.07224"
        rpy="0 0 0" />
      <mass
        value="1.42541" />
      <inertia
        ixx="0.00350322410"
        ixy="0.000001766"
        ixz="-0.0006359"
        iyy="0.00816767704"
        iyz="0.0000003606"
        izz="0.00894456337" />
    </inertial>
    <visual>
      <origin
        xyz="0 0 0"
        rpy="0 0 0" />
      <geometry>
        <mesh
          filename="package://dyros_jet_description/meshes/ankle_roll.stl" />
      </geometry>
      <material
        name="">
        <color
          rgba="0.59216 0.61961 0.65098 1" />
      </material>
    </visual>
    <collision>
      <origin
        xyz="0 0 0"
        rpy="0 0 0" />
      <geometry>
        <mesh
          filename="package://dyros_jet_description/meshes/ankle_roll.stl" />
      </geometry>
    </collision>
  </link>
  <joint
    name="R_AnkleRoll"
    type="revolute">
    <origin
      xyz="0 0 0"
      rpy="0 0 0" />
    <parent
      link="R_AnklePitch_Link" />
    <child
      link="R_AnkleRoll_Link" />
    <axis
      xyz="1 0 0" />
    <limit
      effort="30"
      velocity="1" lower="-3.14" upper="3.14" />
  </joint>
  <link
    name="WaistPitch_Link">
    <inertial>
      <origin
        xyz="0 0 0.1831"
        rpy="0 0 0" />
      <mass
        value="0.18235" />
      <inertia
        ixx="0.00012302926"
        ixy="0"
        ixz="0"
        iyy="0.00065359928"
        iyz="0"
        izz="0.00063093458" />
    </inertial>
    <visual>
      <origin
        xyz="0 0 0"
        rpy="0 0 0" />
      <geometry>
        <mesh
          filename="package://dyros_jet_description/meshes/WaistPitch_Link.stl" />
      </geometry>
      <material
        name="">
        <color
          rgba="0.59216 0.61961 0.65098 1" />
      </material>
    </visual>
    <collision>
      <origin
        xyz="0 0 0"
        rpy="0 0 0" />
      <geometry>
        <mesh
          filename="package://dyros_jet_description/meshes/WaistPitch_Link.stl" />
      </geometry>
    </collision>
  </link>
  <joint
    name="WaistPitch"
    type="revolute">
    <origin
      xyz="0 0 0"
      rpy="0 0 0" />
    <parent
      link="virtual" />
    <child
      link="base_link" />
    <axis
      xyz="0 0 1" />
    <limit
      effort="30"
      velocity="1" lower="-3.14" upper="3.14" />
  </joint>
  <link
    name="WaistYaw_Link">
    <inertial>
      <origin
        xyz="0.0038 -0.00415 0.11424"
        rpy="0 0 0" />
      <mass
        value="14.09938" />
      <inertia
        ixx="0.262766"
        ixy="0"
        ixz="0"
        iyy="0.242504"
        iyz="0"
        izz="0.109346" />
    </inertial>
    <visual>
      <origin
        xyz="0 0 0"
        rpy="0 0 0" />
      <geometry>
        <mesh
          filename="package://dyros_jet_description/meshes/WaistYaw_Link.stl" />
      </geometry>
      <material
        name="">
        <color
          rgba="0.59216 0.61961 0.65098 1" />
      </material>
    </visual>
    <visual>
      <origin
        xyz="-0.16 0 0.11"
        rpy="0 0 0" />
      <geometry>
        <box size= "0.09 0.265 0.225"/>
      </geometry>
      <material
        name="">
        <color
          rgba="0.59216 0.61961 0.65098 1" />
      </material>
    </visual>
    <collision>
      <origin
        xyz="0 0 0"
        rpy="0 0 0" />
      <geometry>
        <mesh
          filename="package://dyros_jet_description/meshes/WaistYaw_Link.stl" />
      </geometry>
    </collision>
    <collision>
      <origin
        xyz="-0.16 0 0.11"
        rpy="0 0 0" />
      <geometry>
        <box size= "0.09 0.265 0.225"/>
      </geometry>
    </collision>
  </link>
  <joint
    name="WaistYaw"
    type="revolute">
    <origin
      xyz="0 0 0.186"
      rpy="0 0 0" />
    <parent
      link="WaistPitch_Link" />
    <child
      link="WaistYaw_Link" />
    <axis
      xyz="-1 0 0" />
    <limit
      effort="30"
      velocity="1" lower="-3.14" upper="3.14" />
  </joint>
  <link
    name="L_ShoulderPitch_Link">
    <inertial>
      <origin
        xyz="-0.00159 -0.00092 0"
        rpy="0 0 0" />
      <mass
        value="0.92796" />
      <inertia
        ixx="0.000473"
        ixy="0"
        ixz="0"
        iyy="0.0015422"
        iyz="0"
        izz="0.00156" />
    </inertial>
    <visual>
      <origin
        xyz="0 0 0"
        rpy="0 0 0" />
      <geometry>
        <mesh
          filename="package://dyros_jet_description/meshes/L_ShoulderPitch_Link.stl" />
      </geometry>
      <material
        name="">
        <color
          rgba="0.59216 0.61961 0.65098 1" />
      </material>
    </visual>
    <collision>
      <origin
        xyz="0 0 0"
        rpy="0 0 0" />
      <geometry>
        <mesh
          filename="package://dyros_jet_description/meshes/L_ShoulderPitch_Link.stl" />
      </geometry>
    </collision>
  </link>
  <joint
    name="L_ShoulderPitch"
    type="revolute">
    <origin
      xyz="0 0.17 0.239"
      rpy="0.5236 0 0" />
    <parent
      link="WaistYaw_Link" />
    <child
      link="L_ShoulderPitch_Link" />
    <axis
      xyz="0 1 0" />
    <limit
      effort="30"
      velocity="1" lower="-3.14" upper="3.14" />
  </joint>
  <link
    name="L_ShoulderRoll_Link">
    <inertial>
      <origin
        xyz="0 0.03197 0.02958"
        rpy="0 0 0" />
      <mass
        value="0.11240" />
      <inertia
        ixx="0.00020404661"
        ixy="0"
        ixz="0"
        iyy="0.00041936488"
        iyz="0.00000671313"
        izz="0.00050880868" />
    </inertial>
    <visual>
      <origin
        xyz="0 0 0"
        rpy="0 0 0" />
      <geometry>
        <mesh
          filename="package://dyros_jet_description/meshes/L_ShoulderRoll_Link.stl" />
      </geometry>
      <material
        name="">
        <color
          rgba="0.59216 0.61961 0.65098 1" />
      </material>
    </visual>
    <collision>
      <origin
        xyz="0 0 0"
        rpy="0 0 0" />
      <geometry>
        <mesh
          filename="package://dyros_jet_description/meshes/L_ShoulderRoll_Link.stl" />
      </geometry>
    </collision>
  </link>
  <joint
    name="L_ShoulderRoll"
    type="revolute">
    <origin
      xyz="0 0 0"
      rpy="0 0 0" />
    <parent
      link="L_ShoulderPitch_Link" />
    <child
      link="L_ShoulderRoll_Link" />
    <axis
      xyz="1 0 0" />
    <limit
      effort="30"
      velocity="1" lower="-2.1" upper="-0.2" />
  </joint>
  <link
    name="L_ShoulderYaw_Link">
    <inertial>
      <origin
        xyz="-0.00022 0.20695 -0.00024"
        rpy="0 0 0" />
      <mass
        value="1.75149" />
      <inertia
        ixx="0.01201096136"
        ixy="-0.00003314922"
        ixz="0"
        iyy="0.00139869678"
        iyz="-0.00006758314"
        izz="0.08761122082" />
    </inertial>
    <visual>
      <origin
        xyz="0 0 0"
        rpy="0 0 0" />
      <geometry>
        <mesh
          filename="package://dyros_jet_description/meshes/L_ShoulderYaw_Link.stl" />
      </geometry>
      <material
        name="">
        <color
          rgba="0.59216 0.61961 0.65098 1" />
      </material>
    </visual>
    <collision>
      <origin
        xyz="0 0 0"
        rpy="0 0 0" />
      <geometry>
        <mesh
          filename="package://dyros_jet_description/meshes/L_ShoulderYaw_Link.stl" />
      </geometry>
    </collision>
  </link>
  <joint
    name="L_ShoulderYaw"
    type="revolute">
    <origin
      xyz="0 0 0.02886"
      rpy="0 0 0" />
    <parent
      link="L_ShoulderRoll_Link" />
    <child
      link="L_ShoulderYaw_Link" />
    <axis
      xyz="0 1 0" />
    <limit
      effort="30"
      velocity="1" lower="-3.14" upper="3.14" />
  </joint>
  <link
    name="L_ElbowRoll_Link">
    <inertial>
      <origin
        xyz="-0.00013 0.06984 0.02766"
        rpy="0 0 0" />
      <mass
        value="0.83342" />
      <inertia
        ixx="0.00111008305"
        ixy="0.00000055705"
        ixz="-0.00000036229"
        iyy="0.00113664167"
        iyz="0.00010148619"
        izz="0.00071417056" />
    </inertial>
    <visual>
      <origin
        xyz="0 0 0"
        rpy="0 0 0" />
      <geometry>
        <mesh
          filename="package://dyros_jet_description/meshes/L_ElbowRoll_Link.stl" />
      </geometry>
      <material
        name="">
        <color
          rgba="0.59216 0.61961 0.65098 1" />
      </material>
    </visual>
    <collision>
      <origin
        xyz="0 0 0"
        rpy="0 0 0" />
      <geometry>
        <mesh
          filename="package://dyros_jet_description/meshes/L_ElbowRoll_Link.stl" />
      </geometry>
    </collision>
  </link>
  <joint
    name="L_ElbowRoll"
    type="revolute">
    <origin
      xyz="0 0.294 0"
      rpy="0 0 0" />
    <parent
      link="L_ShoulderYaw_Link" />
    <child
      link="L_ElbowRoll_Link" />
    <axis
      xyz="1 0 0" />
    <limit
      effort="30"
      velocity="1" lower="-2.8" upper="0.3" />
  </joint>
  <link
    name="L_WristYaw_Link">
    <inertial>
      <origin
        xyz="-0.0006 0.25889 0"
        rpy="0 0 0" />
      <mass
        value="0.52391" />
      <inertia
        ixx="0.00309173456"
        ixy="0.00001569255"
        ixz="0"
        iyy="0.00041001585"
        iyz="0"
        izz="0.00332083933" />
    </inertial>
    <visual>
      <origin
        xyz="0 0 0"
        rpy="0 0 0" />
      <geometry>
        <mesh
          filename="package://dyros_jet_description/meshes/L_WristYaw_Link.stl" />
      </geometry>
      <material
        name="">
        <color
          rgba="0.59216 0.61961 0.65098 1" />
      </material>
    </visual>
    <collision>
      <origin
        xyz="0 0 0"
        rpy="0 0 0" />
      <geometry>
        <mesh
          filename="package://dyros_jet_description/meshes/L_WristYaw_Link.stl" />
      </geometry>
    </collision>
  </link>
  <joint
    name="L_WristYaw"
    type="revolute">
    <origin
      xyz="0 0 0.075"
      rpy="0 0 0" />
    <parent
      link="L_ElbowRoll_Link" />
    <child
      link="L_WristYaw_Link" />
    <axis
      xyz="0 1 0" />
    <limit
      effort="30"
      velocity="1" lower="-3.14" upper="3.14" />
  </joint>
  <link
    name="L_WristRoll_Link">
    <inertial>
      <origin
        xyz="0 -0.029698 0"
        rpy="0 0 0" />
      <mass
        value="0.07856" />
      <inertia
        ixx="0.00010228871"
        ixy="0"
        ixz="0"
        iyy="0.00010761509"
        iyz="-0.00000303386"
        izz="0.00002580006" />
    </inertial>
    <visual>
      <origin
        xyz="0 0 0"
        rpy="0 0 0" />
      <geometry>
        <mesh
          filename="package://dyros_jet_description/meshes/L_WristRoll_Link.stl" />
      </geometry>
      <material
        name="">
        <color
          rgba="0.59216 0.61961 0.65098 1" />
      </material>
    </visual>
    <collision>
      <origin
        xyz="0 0 0"
        rpy="0 0 0" />
      <geometry>
        <mesh
          filename="package://dyros_jet_description/meshes/L_WristRoll_Link.stl" />
      </geometry>
    </collision>
  </link>
  <joint
    name="L_WristRoll"
    type="revolute">
    <origin
      xyz="-0.00015 0.3085 0"
      rpy="0 0 0" />
    <parent
      link="L_WristYaw_Link" />
    <child
      link="L_WristRoll_Link" />
    <axis
      xyz="1 0 0" />
    <limit
      effort="30"
      velocity="1" lower="-3.14" upper="3.14" />
  </joint>
  <link
    name="L_HandYaw_Link">
    <inertial>
      <origin
        xyz="0 0.18510 0.00220"
        rpy="0 0 0" />
      <mass
        value="1.20640" />
      <inertia
        ixx="0.00607402214"
        ixy="0"
        ixz="0"
        iyy="0.00224926768"
        iyz="0.00009697326"
        izz="0.00759001230" />
    </inertial>
    <visual>
      <origin
        xyz="0 0 0"
        rpy="0 0 0" />
      <geometry>
        <mesh
          filename="package://dyros_jet_description/meshes/L_HandYaw_Link.stl" />
      </geometry>
      <material
        name="">
        <color
          rgba="0.59216 0.61961 0.65098 1" />
      </material>
    </visual>
    <collision>
      <origin
        xyz="0 0 0"
        rpy="0 0 0" />
      <geometry>
        <mesh
          filename="package://dyros_jet_description/meshes/L_HandYaw_Link.stl" />
      </geometry>
    </collision>
  </link>
  <joint
    name="L_HandYaw"
    type="revolute">
    <origin
      xyz="0 0 0"
      rpy="5.5511E-17 0 -3.9443E-31" />
    <parent
      link="L_WristRoll_Link" />
    <child
      link="L_HandYaw_Link" />
    <axis
      xyz="0 1 0" />
    <limit
      effort="30"
      velocity="1" lower="-3.14" upper="3.14" />
  </joint>

  <link
    name="R_ShoulderPitch_Link">
    <inertial>
      <origin
        xyz="-0.00159 0.00092 0"
        rpy="0 0 0" />
      <mass
        value="0.92796" />
      <inertia
        ixx="0.000473"
        ixy="0"
        ixz="0"
        iyy="0.0015422"
        iyz="0"
        izz="0.00156" />
    </inertial>
    <visual>
      <origin
        xyz="0 0 0"
        rpy="0 0 0" />
      <geometry>
        <mesh
          filename="package://dyros_jet_description/meshes/R_ShoulderPitch_Link.stl" />
      </geometry>
      <material
        name="">
        <color
          rgba="0.59216 0.61961 0.65098 1" />
      </material>
    </visual>
    <collision>
      <origin
        xyz="0 0 0"
        rpy="0 0 0" />
      <geometry>
        <mesh
          filename="package://dyros_jet_description/meshes/R_ShoulderPitch_Link.stl" />
      </geometry>
    </collision>
  </link>
  <joint
    name="R_ShoulderPitch"
    type="revolute">
    <origin
      xyz="0 -0.17 0.239"
      rpy="-0.5236 0 0" />
    <parent
      link="WaistYaw_Link" />
    <child
      link="R_ShoulderPitch_Link" />
    <axis
      xyz="0 -1 0" />
    <limit
      effort="30"
      velocity="1" lower="-3.14" upper="3.14" />
  </joint>
  <link
    name="R_ShoulderRoll_Link">
    <inertial>
      <origin
        xyz="0 -0.03197 -0.02958"
        rpy="0 0 0" />
      <mass
        value="0.11240" />
      <inertia
        ixx="0.00020404661"
        ixy="0"
        ixz="0"
        iyy="0.00041936488"        
        iyz="-0.00000671313"
        izz="0.00050880868" />
    </inertial>
    <visual>
      <origin
        xyz="0 0 0"
        rpy="0 0 0" />
      <geometry>
        <mesh
          filename="package://dyros_jet_description/meshes/R_ShoulderRoll_Link.stl" />
      </geometry>
      <material
        name="">
        <color
          rgba="0.59216 0.61961 0.65098 1" />
      </material>
    </visual>
    <collision>
      <origin
        xyz="0 0 0"
        rpy="0 0 0" />
      <geometry>
        <mesh
          filename="package://dyros_jet_description/meshes/R_ShoulderRoll_Link.stl" />
      </geometry>
    </collision>
  </link>
  <joint
    name="R_ShoulderRoll"
    type="revolute">
    <origin
      xyz="0 0 0"
      rpy="0 0 0" />
    <parent
      link="R_ShoulderPitch_Link" />
    <child
      link="R_ShoulderRoll_Link" />
    <axis
      xyz="1 0 0" />
    <limit
      effort="30"
      velocity="1" lower="0.2" upper="2.1" />
  </joint>
  <link
    name="R_ShoulderYaw_Link">
    <inertial>
      <origin
        xyz="-0.00022 -0.20696 -0.00024 "
        rpy="0 0 0" />
      <mass
        value="1.75149" />
      <inertia
        ixx="0.01201096136"
        ixy="0.00003314922"
        ixz="0.00000009112"
        iyy="0.00139888450"
        iyz="0.00002113268"
        izz="0.01260101996" />
    </inertial>
    <visual>
      <origin
        xyz="0 0 0"
        rpy="0 0 0" />
      <geometry>
        <mesh
          filename="package://dyros_jet_description/meshes/R_ShoulderYaw_Link.stl" />
      </geometry>
      <material
        name="">
        <color
          rgba="0.59216 0.61961 0.65098 1" />
      </material>
    </visual>
    <collision>
      <origin
        xyz="0 0 0"
        rpy="0 0 0" />
      <geometry>
        <mesh
          filename="package://dyros_jet_description/meshes/R_ShoulderYaw_Link.stl" />
      </geometry>
    </collision>
  </link>
  <joint
    name="R_ShoulderYaw"
    type="revolute">
    <origin
      xyz="0 0 0.02886"
      rpy="0 0 0" />
    <parent
      link="R_ShoulderRoll_Link" />
    <child
      link="R_ShoulderYaw_Link" />
    <axis
      xyz="0 -1 0" />
    <limit
      effort="30"
      velocity="1" lower="-3.14" upper="3.14" />
  </joint>
  <link
    name="R_ElbowRoll_Link">
    <inertial>
      <origin
        xyz="0.00013 -0.02766 0.06984"
        rpy="0 0 0" />
      <mass
        value="0.83342" />
      <inertia
        ixx="0.00111008305"
        ixy="0.00000036229"
        ixz="0.00000055755"
        iyy="0.00071417056"
        iyz="0.00010148619"
        izz="0.00113664167" />
    </inertial>
    <visual>
      <origin
        xyz="0 0 0"
        rpy="0 0 0" />
      <geometry>
        <mesh
          filename="package://dyros_jet_description/meshes/R_ElbowRoll_Link.stl" />
      </geometry>
      <material
        name="">
        <color
          rgba="0.59216 0.61961 0.65098 1" />
      </material>
    </visual>
    <collision>
      <origin
        xyz="0 0 0"
        rpy="0 0 0" />
      <geometry>
        <mesh
          filename="package://dyros_jet_description/meshes/R_ElbowRoll_Link.stl" />
      </geometry>
    </collision>
  </link>
  <joint
    name="R_ElbowRoll"
    type="revolute">
    <origin
      xyz="0 -0.294 0"
      rpy="0 0 0" />
    <parent
      link="R_ShoulderYaw_Link" />
    <child
      link="R_ElbowRoll_Link" />
    <axis
      xyz="1 0 0" />
    <limit
      effort="30"
      velocity="1" lower="-0.3" upper="2.8" />
  </joint>
  <link
    name="R_WristYaw_Link">
    <inertial>
      <origin
        xyz="-0.0006 -0.25889 0"
        rpy="0 0 0" />
      <mass
        value="0.52391" />
      <inertia
        ixx="0.00309173456"
        ixy="0.00001569255"
        ixz="0"
        iyy="0.00041001585"
        iyz="0"
        izz="0.00332083933" />
    </inertial>
    <visual>
      <origin
        xyz="0 0 0"
        rpy="0 0 0" />
      <geometry>
        <mesh
          filename="package://dyros_jet_description/meshes/R_WristYaw_Link.stl" />
      </geometry>
      <material
        name="">
        <color
          rgba="0.59216 0.61961 0.65098 1" />
      </material>
    </visual>
    <collision>
      <origin
        xyz="0 0 0"
        rpy="0 0 0" />
      <geometry>
        <mesh
          filename="package://dyros_jet_description/meshes/R_WristYaw_Link.stl" />
      </geometry>
    </collision>
  </link>
  <joint
    name="R_WristYaw"
    type="revolute">
    <origin
      xyz="0 0 0.075"
      rpy="0 0 0" />
    <parent
      link="R_ElbowRoll_Link" />
    <child
      link="R_WristYaw_Link" />
    <axis
      xyz="0 -1 0" />
    <limit
      effort="30"
      velocity="1" lower="-3.14" upper="3.14" />
  </joint>
  <link
    name="R_WristRoll_Link">
    <inertial>
      <origin
        xyz="0 -0.02928 -0.00350"
        rpy="0 0 0" />
      <mass
        value="0.07856" />
      <inertia
        ixx="0.00010228871"
        ixy="0"
        ixz="0"
        iyy="0.00010761509"
        iyz="0.00000303386"
        izz="0.00002580006" />
    </inertial>
    <visual>
      <origin
        xyz="0 0 0"
        rpy="0 0 0" />
      <geometry>
        <mesh
          filename="package://dyros_jet_description/meshes/R_WristRoll_Link.stl" />
      </geometry>
      <material
        name="">
        <color
          rgba="0.59216 0.61961 0.65098 1" />
      </material>
    </visual>
    <collision>
      <origin
        xyz="0 0 0"
        rpy="0 0 0" />
      <geometry>
        <mesh
          filename="package://dyros_jet_description/meshes/R_WristRoll_Link.stl" />
      </geometry>
    </collision>
  </link>
  <joint
    name="R_WristRoll"
    type="revolute">
    <origin
      xyz="0 -0.3085 0"
      rpy="0 0 0" />
    <parent
      link="R_WristYaw_Link" />
    <child
      link="R_WristRoll_Link" />
    <axis
      xyz="1 0 0" />
    <limit
      effort="30"
      velocity="1" lower="-1.9" upper="1.9" />
  </joint>
  <link
    name="R_HandYaw_Link">
    <inertial>
      <origin
        xyz="-0.00380 0.006 -0.14610"
        rpy="0 0 0" />
      <mass
        value="1.20640" />
      <inertia
        ixx="0.00759001230"
        ixy="0"
        ixz="0.00009697326"
        iyy="0.00607402214"
        iyz="0"
        izz="0.00224340618" />
    </inertial>
    <visual>
      <origin
        xyz="0 0 0"
        rpy="0 0 0" />
      <geometry>
        <mesh
          filename="package://dyros_jet_description/meshes/R_HandYaw_new.stl" />
      </geometry>
      <material
        name="">
        <color
          rgba="0.59216 0.61961 0.65098 1" />
      </material>
    </visual>
    <collision>
      <origin
        xyz="0 0 0"
        rpy="0 0 0" />
      <geometry>
        <mesh
          filename="package://dyros_jet_description/meshes/R_HandYaw_new.stl" />
      </geometry>
    </collision>
  </link>
  <joint
    name="R_HandYaw"
    type="revolute">
    <origin
      xyz="0 0 0"
      rpy="0 0 0" />
    <parent
      link="R_WristRoll_Link" />
    <child
      link="R_HandYaw_Link" />
    <axis
      xyz="0 -1 0" />
    <limit
      effort="30"
      velocity="1" lower="-3.14" upper="3.14" />
  </joint>
</robot>
